<sdf version='1.6'>
  <world name='default'>
    <model name='ground_plane'>
      <static>1</static>
      <link name='link'>
        <collision name='collision'>
          <geometry>
            <plane>
              <normal>0 0 1</normal>
              <size>100 100</size>
            </plane>
          </geometry>
          <surface>
            <friction>
              <ode>
                <mu>100</mu>
                <mu2>50</mu2>
              </ode>
              <torsional>
                <ode/>
              </torsional>
            </friction>
            <contact>
              <ode/>
            </contact>
            <bounce/>
          </surface>
          <max_contacts>10</max_contacts>
        </collision>
        <visual name='visual'>
          <cast_shadows>0</cast_shadows>
          <geometry>
            <plane>
              <normal>0 0 1</normal>
              <size>100 100</size>
            </plane>
          </geometry>
          <material>
            <script>
              <uri>file://media/materials/scripts/gazebo.material</uri>
              <name>Gazebo/Grey</name>
            </script>
          </material>
        </visual>
        <self_collide>0</self_collide>
        <kinematic>0</kinematic>
      </link>
    </model>
    <light name='sun' type='directional'>
      <cast_shadows>1</cast_shadows>
      <pose frame=''>0 0 10 0 -0 0</pose>
      <diffuse>0.8 0.8 0.8 1</diffuse>
      <specular>0.2 0.2 0.2 1</specular>
      <attenuation>
        <range>1000</range>
        <constant>0.9</constant>
        <linear>0.01</linear>
        <quadratic>0.001</quadratic>
      </attenuation>
      <direction>-0.5 0.1 -0.9</direction>
    </light>
    <model name='nasa_arena'>
      <pose frame=''>0 0 0 0 -0 0</pose>
      <static>1</static>
      <link name='body'>
        <inertial>
          <mass>0.1</mass>
          <inertia>
            <ixx>1</ixx>
            <ixy>0</ixy>
            <ixz>0</ixz>
            <iyy>1</iyy>
            <iyz>0</iyz>
            <izz>1</izz>
          </inertia>
        </inertial>
        <visual name='Arena_Visual'>
          <geometry>
            <mesh>
              <uri>model://amee_gazebo/meshes/chessboard.dae</uri>
            </mesh>
          </geometry>
        </visual>
        <collision name='Arena_Surface'>
          <geometry>
            <mesh>
              <uri>model://amee_gazebo/meshes/chessboard.dae</uri>
            </mesh>
          </geometry>
          <surface>
            <contact>
              <ode>
                <max_vel>1</max_vel>
              </ode>
            </contact>
            <bounce/>
            <friction>
              <torsional>
                <ode/>
              </torsional>
              <ode/>
            </friction>
          </surface>
          <max_contacts>10</max_contacts>
        </collision>
        <self_collide>0</self_collide>
        <kinematic>0</kinematic>
      </link>
    </model>
    <gravity>0 0 -9.8</gravity>
    <magnetic_field>6e-06 2.3e-05 -4.2e-05</magnetic_field>
    <atmosphere type='adiabatic'/>
    <physics name='default_physics' default='0' type='ode'>
      <max_step_size>0.001</max_step_size>
      <real_time_factor>1</real_time_factor>
      <real_time_update_rate>1000</real_time_update_rate>
    </physics>
    <scene>
      <ambient>0.4 0.4 0.4 1</ambient>
      <background>0.7 0.7 0.7 1</background>
      <shadows>1</shadows>
    </scene>
    <spherical_coordinates>
      <surface_model>EARTH_WGS84</surface_model>
      <latitude_deg>0</latitude_deg>
      <longitude_deg>0</longitude_deg>
      <elevation>0</elevation>
      <heading_deg>0</heading_deg>
    </spherical_coordinates>
    <model name='amee'>
      <link name='base_link'>
        <pose frame=''>0 0 0 0 -0 0</pose>
        <inertial>
          <pose frame=''>0 0 0.165375 0 -0 0</pose>
          <mass>3.051</mass>
          <inertia>
            <ixx>0.28</ixx>
            <ixy>0</ixy>
            <ixz>0</ixz>
            <iyy>0.42</iyy>
            <iyz>0</iyz>
            <izz>0.17</izz>
          </inertia>
        </inertial>
        <collision name='base_link_fixed_joint_lump__chassis_collision'>
          <pose frame=''>0 0 0.165375 0 -0 0</pose>
          <geometry>
            <box>
              <size>0.627 0.4731 0.136</size>
            </box>
          </geometry>
          <surface>
            <contact>
              <ode/>
            </contact>
            <friction>
              <ode>
                <mu>0.2</mu>
                <mu2>0.2</mu2>
              </ode>
              <torsional>
                <ode/>
              </torsional>
            </friction>
            <bounce/>
          </surface>
          <max_contacts>10</max_contacts>
        </collision>
        <visual name='base_link_fixed_joint_lump__chassis_visual'>
          <pose frame=''>0 0 0.165375 0 -0 0</pose>
          <geometry>
            <mesh>
              <scale>1 1 1</scale>
              <uri>/home/jericho/catkin_ws/src/usr_simulation/amee_description/meshes/visual/chassis.dae</uri>
            </mesh>
          </geometry>
          <material>
            <script>
              <name>Gazebo/Grey</name>
              <uri>file://media/materials/scripts/gazebo.material</uri>
            </script>
          </material>
        </visual>
        <velocity_decay/>
        <gravity>1</gravity>
        <velocity_decay/>
        <self_collide>0</self_collide>
        <kinematic>0</kinematic>
      </link>
      <link name='left_front_wheel_link'>
        <pose frame=''>0.2525 0.305 0.165375 0 -0 0</pose>
        <inertial>
          <pose frame=''>0 0 0 0 -0 0</pose>
          <mass>8.6</mass>
          <inertia>
            <ixx>0.0785782</ixx>
            <ixy>0</ixy>
            <ixz>0</ixz>
            <iyy>0.0785782</iyy>
            <iyz>0</iyz>
            <izz>0.10514</izz>
          </inertia>
        </inertial>
        <collision name='left_front_wheel_link_collision'>
          <pose frame=''>0 0 0 1.5708 -0 0</pose>
          <geometry>
            <cylinder>
              <length>0.125</length>
              <radius>0.145</radius>
            </cylinder>
          </geometry>
          <surface>
            <contact>
              <ode/>
            </contact>
            <friction>
              <ode>
                <mu>5</mu>
                <mu2>5</mu2>
              </ode>
              <torsional>
                <ode/>
              </torsional>
            </friction>
            <bounce/>
          </surface>
          <max_contacts>10</max_contacts>
        </collision>
        <visual name='left_front_wheel_link_visual'>
          <pose frame=''>0 0 0 1.5708 -0 0</pose>
          <geometry>
            <cylinder>
              <length>0.125</length>
              <radius>0.145</radius>
            </cylinder>
          </geometry>
          <material>
            <script>
              <name>Gazebo/DarkGrey</name>
              <uri>file://media/materials/scripts/gazebo.material</uri>
            </script>
          </material>
        </visual>
        <gravity>1</gravity>
        <velocity_decay/>
        <self_collide>0</self_collide>
        <kinematic>0</kinematic>
      </link>
      <joint name='left_front_wheel' type='revolute'>
        <child>left_front_wheel_link</child>
        <parent>base_link</parent>
        <axis>
          <xyz>0 1 0</xyz>
          <limit>
            <lower>-1e+16</lower>
            <upper>1e+16</upper>
          </limit>
          <dynamics>
            <spring_reference>0</spring_reference>
            <spring_stiffness>0</spring_stiffness>
          </dynamics>
          <use_parent_model_frame>1</use_parent_model_frame>
        </axis>
      </joint>
      <link name='left_rear_wheel_link'>
        <pose frame=''>-0.2525 0.305 0.165375 0 -0 0</pose>
        <inertial>
          <pose frame=''>0 0 0 0 -0 0</pose>
          <mass>8.6</mass>
          <inertia>
            <ixx>0.0785782</ixx>
            <ixy>0</ixy>
            <ixz>0</ixz>
            <iyy>0.0785782</iyy>
            <iyz>0</iyz>
            <izz>0.10514</izz>
          </inertia>
        </inertial>
        <collision name='left_rear_wheel_link_collision'>
          <pose frame=''>0 0 0 1.5708 -0 0</pose>
          <geometry>
            <cylinder>
              <length>0.125</length>
              <radius>0.145</radius>
            </cylinder>
          </geometry>
          <surface>
            <contact>
              <ode/>
            </contact>
            <friction>
              <ode>
                <mu>5</mu>
                <mu2>5</mu2>
              </ode>
              <torsional>
                <ode/>
              </torsional>
            </friction>
            <bounce/>
          </surface>
          <max_contacts>10</max_contacts>
        </collision>
        <visual name='left_rear_wheel_link_visual'>
          <pose frame=''>0 0 0 1.5708 -0 0</pose>
          <geometry>
            <cylinder>
              <length>0.125</length>
              <radius>0.145</radius>
            </cylinder>
          </geometry>
          <material>
            <script>
              <name>Gazebo/DarkGrey</name>
              <uri>file://media/materials/scripts/gazebo.material</uri>
            </script>
          </material>
        </visual>
        <gravity>1</gravity>
        <velocity_decay/>
        <self_collide>0</self_collide>
        <kinematic>0</kinematic>
      </link>
      <joint name='left_rear_wheel' type='revolute'>
        <child>left_rear_wheel_link</child>
        <parent>base_link</parent>
        <axis>
          <xyz>0 1 0</xyz>
          <limit>
            <lower>-1e+16</lower>
            <upper>1e+16</upper>
          </limit>
          <dynamics>
            <spring_reference>0</spring_reference>
            <spring_stiffness>0</spring_stiffness>
          </dynamics>
          <use_parent_model_frame>1</use_parent_model_frame>
        </axis>
      </joint>
      <link name='right_front_wheel_link'>
        <pose frame=''>0.2525 -0.305 0.165375 -3.14159 -0 0</pose>
        <inertial>
          <pose frame=''>0 0 0 0 -0 0</pose>
          <mass>8.6</mass>
          <inertia>
            <ixx>0.0785782</ixx>
            <ixy>0</ixy>
            <ixz>0</ixz>
            <iyy>0.0785782</iyy>
            <iyz>0</iyz>
            <izz>0.10514</izz>
          </inertia>
        </inertial>
        <collision name='right_front_wheel_link_collision'>
          <pose frame=''>0 0 0 1.5708 -0 0</pose>
          <geometry>
            <cylinder>
              <length>0.125</length>
              <radius>0.145</radius>
            </cylinder>
          </geometry>
          <surface>
            <contact>
              <ode/>
            </contact>
            <friction>
              <ode>
                <mu>5</mu>
                <mu2>5</mu2>
              </ode>
              <torsional>
                <ode/>
              </torsional>
            </friction>
            <bounce/>
          </surface>
          <max_contacts>10</max_contacts>
        </collision>
        <visual name='right_front_wheel_link_visual'>
          <pose frame=''>0 0 0 1.5708 -0 0</pose>
          <geometry>
            <cylinder>
              <length>0.125</length>
              <radius>0.145</radius>
            </cylinder>
          </geometry>
          <material>
            <script>
              <name>Gazebo/DarkGrey</name>
              <uri>file://media/materials/scripts/gazebo.material</uri>
            </script>
          </material>
        </visual>
        <gravity>1</gravity>
        <velocity_decay/>
        <self_collide>0</self_collide>
        <kinematic>0</kinematic>
      </link>
      <joint name='right_front_wheel' type='revolute'>
        <child>right_front_wheel_link</child>
        <parent>base_link</parent>
        <axis>
          <xyz>0 1 0</xyz>
          <limit>
            <lower>-1e+16</lower>
            <upper>1e+16</upper>
          </limit>
          <dynamics>
            <spring_reference>0</spring_reference>
            <spring_stiffness>0</spring_stiffness>
          </dynamics>
          <use_parent_model_frame>1</use_parent_model_frame>
        </axis>
      </joint>
      <link name='right_rear_wheel_link'>
        <pose frame=''>-0.2525 -0.305 0.165375 -3.14159 -0 0</pose>
        <inertial>
          <pose frame=''>0 0 0 0 -0 0</pose>
          <mass>8.6</mass>
          <inertia>
            <ixx>0.0785782</ixx>
            <ixy>0</ixy>
            <ixz>0</ixz>
            <iyy>0.0785782</iyy>
            <iyz>0</iyz>
            <izz>0.10514</izz>
          </inertia>
        </inertial>
        <collision name='right_rear_wheel_link_collision'>
          <pose frame=''>0 0 0 1.5708 -0 0</pose>
          <geometry>
            <cylinder>
              <length>0.125</length>
              <radius>0.145</radius>
            </cylinder>
          </geometry>
          <surface>
            <contact>
              <ode/>
            </contact>
            <friction>
              <ode>
                <mu>5</mu>
                <mu2>5</mu2>
              </ode>
              <torsional>
                <ode/>
              </torsional>
            </friction>
            <bounce/>
          </surface>
          <max_contacts>10</max_contacts>
        </collision>
        <visual name='right_rear_wheel_link_visual'>
          <pose frame=''>0 0 0 1.5708 -0 0</pose>
          <geometry>
            <cylinder>
              <length>0.125</length>
              <radius>0.145</radius>
            </cylinder>
          </geometry>
          <material>
            <script>
              <name>Gazebo/DarkGrey</name>
              <uri>file://media/materials/scripts/gazebo.material</uri>
            </script>
          </material>
        </visual>
        <gravity>1</gravity>
        <velocity_decay/>
        <self_collide>0</self_collide>
        <kinematic>0</kinematic>
      </link>
      <joint name='right_rear_wheel' type='revolute'>
        <child>right_rear_wheel_link</child>
        <parent>base_link</parent>
        <axis>
          <xyz>0 1 0</xyz>
          <limit>
            <lower>-1e+16</lower>
            <upper>1e+16</upper>
          </limit>
          <dynamics>
            <spring_reference>0</spring_reference>
            <spring_stiffness>0</spring_stiffness>
          </dynamics>
          <use_parent_model_frame>1</use_parent_model_frame>
        </axis>
      </joint>
      <link name='sled_hoz'>
        <pose frame=''>0 0 0.253625 0 -0 0</pose>
        <inertial>
          <pose frame=''>-0.082135 0 0.186963 0 -0 0</pose>
          <mass>15.25</mass>
          <inertia>
            <ixx>0.436489</ixx>
            <ixy>-5.6e-05</ixy>
            <ixz>0.0891819</ixz>
            <iyy>0.378518</iyy>
            <iyz>4.5e-05</iyz>
            <izz>0.377697</izz>
          </inertia>
        </inertial>
        <collision name='sled_hoz_collision'>
          <pose frame=''>0 0 0 0 -0 0</pose>
          <geometry>
            <box>
              <size>0.245 0.442 0.0405</size>
            </box>
          </geometry>
          <surface>
            <contact>
              <ode/>
            </contact>
            <friction>
              <ode>
                <mu>0.2</mu>
                <mu2>0.2</mu2>
              </ode>
              <torsional>
                <ode/>
              </torsional>
            </friction>
            <bounce/>
          </surface>
          <max_contacts>10</max_contacts>
        </collision>
        <collision name='sled_hoz_fixed_joint_lump__sled_ver_collision_1'>
          <pose frame=''>-0.10225 0 0.23275 0 -0 0</pose>
          <geometry>
            <box>
              <size>0.0405 0.35 0.425</size>
            </box>
          </geometry>
          <surface>
            <contact>
              <ode/>
            </contact>
            <friction>
              <ode>
                <mu>0.2</mu>
                <mu2>0.2</mu2>
              </ode>
              <torsional>
                <ode/>
              </torsional>
            </friction>
            <bounce/>
          </surface>
          <max_contacts>10</max_contacts>
        </collision>
        <visual name='sled_hoz_visual'>
          <pose frame=''>0 0 0 0 -0 0</pose>
          <geometry>
            <mesh>
              <scale>1 1 1</scale>
              <uri>/home/jericho/catkin_ws/src/usr_simulation/amee_description/meshes/visual/sled.dae</uri>
            </mesh>
          </geometry>
          <material>
            <script>
              <name>Gazebo/Grey</name>
              <uri>file://media/materials/scripts/gazebo.material</uri>
            </script>
          </material>
        </visual>
        <visual name='sled_hoz_fixed_joint_lump__sled_ver_visual_1'>
          <pose frame=''>-0.10225 0 0.23275 0 -0 0</pose>
          <geometry>
            <box>
              <size>0.001 0.001 0.001</size>
            </box>
          </geometry>
          <material>
            <script>
              <name>Gazebo/Grey</name>
              <uri>file://media/materials/scripts/gazebo.material</uri>
            </script>
          </material>
        </visual>
        <velocity_decay/>
        <gravity>1</gravity>
        <velocity_decay/>
        <self_collide>0</self_collide>
        <kinematic>0</kinematic>
      </link>
      <joint name='sled_joint' type='prismatic'>
        <child>sled_hoz</child>
        <parent>base_link</parent>
        <axis>
          <xyz>1 0 0</xyz>
          <limit>
            <lower>-0.25225</lower>
            <upper>0.12975</upper>
            <effort>1000</effort>
            <velocity>0.1</velocity>
          </limit>
          <dynamics>
            <damping>100</damping>
            <friction>1</friction>
            <spring_reference>0</spring_reference>
            <spring_stiffness>0</spring_stiffness>
          </dynamics>
          <use_parent_model_frame>1</use_parent_model_frame>
        </axis>
      </joint>
      <link name='arm_upper'>
        <pose frame=''>-0.10225 0 0.698875 0 -0 0</pose>
        <inertial>
          <pose frame=''>0.003439 1.9e-05 -0.001958 0 -0 0</pose>
          <mass>2.51</mass>
          <inertia>
            <ixx>0.0424052</ixx>
            <ixy>-4.01715e-05</ixy>
            <ixz>-0.0157758</ixz>
            <iyy>0.0598245</iyy>
            <iyz>2.2871e-05</iyz>
            <izz>0.0774198</izz>
          </inertia>
        </inertial>
        <collision name='arm_upper_collision'>
          <pose frame=''>0.20575 0 0 0 -0 0</pose>
          <geometry>
            <box>
              <size>0.452 0.429 0.0405</size>
            </box>
          </geometry>
          <surface>
            <contact>
              <ode/>
            </contact>
            <friction>
              <ode>
                <mu>0.2</mu>
                <mu2>0.2</mu2>
              </ode>
              <torsional>
                <ode/>
              </torsional>
            </friction>
            <bounce/>
          </surface>
          <max_contacts>10</max_contacts>
        </collision>
        <collision name='arm_upper_fixed_joint_lump__arm_lower_collision_1'>
          <pose frame=''>0.577627 0 -0.155563 0 0.785398 0</pose>
          <geometry>
            <box>
              <size>0.44 0.429 0.0405</size>
            </box>
          </geometry>
          <surface>
            <contact>
              <ode/>
            </contact>
            <friction>
              <ode>
                <mu>0.2</mu>
                <mu2>0.2</mu2>
              </ode>
              <torsional>
                <ode/>
              </torsional>
            </friction>
            <bounce/>
          </surface>
          <max_contacts>10</max_contacts>
        </collision>
        <visual name='arm_upper_visual'>
          <pose frame=''>0.20575 0 0 0 -0 0</pose>
          <geometry>
            <mesh>
              <scale>1 1 1</scale>
              <uri>/home/jericho/catkin_ws/src/usr_simulation/amee_description/meshes/visual/arms_visual.dae</uri>
            </mesh>
          </geometry>
          <material>
            <script>
              <name>Gazebo/Grey</name>
              <uri>file://media/materials/scripts/gazebo.material</uri>
            </script>
          </material>
        </visual>
        <visual name='arm_upper_fixed_joint_lump__arm_lower_visual_1'>
          <pose frame=''>0.577627 0 -0.155563 0 0.785398 0</pose>
          <geometry>
            <box>
              <size>0.001 0.001 0.001</size>
            </box>
          </geometry>
          <material>
            <script>
              <name>script</name>
              <uri>file://media/materials/scripts/gazebo.material</uri>
            </script>
          </material>
        </visual>
        <visual name='arm_upper_fixed_joint_lump__ZED_left_camera_visual_2'>
          <pose frame=''>0.394294 0.06775 0.02777 0 1.57 0</pose>
          <geometry>
            <cylinder>
              <length>0.031</length>
              <radius>0.007</radius>
            </cylinder>
          </geometry>
          <material>
            <script>
              <uri>__default__</uri>
              <name>__default__</name>
            </script>
          </material>
        </visual>
        <visual name='arm_upper_fixed_joint_lump__ZED_center_visual_3'>
          <pose frame=''>0.394294 0.00775 0.02777 0 -0 0</pose>
          <geometry>
            <mesh>
              <scale>1 1 1</scale>
              <uri>/home/jericho/catkin_ws/src/usr_simulation/amee_description/urdf/ZED.stl</uri>
            </mesh>
          </geometry>
        </visual>
        <visual name='arm_upper_fixed_joint_lump__ZED_right_camera_visual_4'>
          <pose frame=''>0.394294 -0.05225 0.02777 0 1.57 0</pose>
          <geometry>
            <cylinder>
              <length>0.031</length>
              <radius>0.007</radius>
            </cylinder>
          </geometry>
        </visual>
        <velocity_decay/>
        <velocity_decay/>
        <gravity>1</gravity>
        <velocity_decay/>
        <sensor name='stereo_camera' type='multicamera'>
          <update_rate>30</update_rate>
          <camera name='left'>
            <horizontal_fov>1.39626</horizontal_fov>
            <image>
              <width>640</width>
              <height>480</height>
              <format>R8G8B8</format>
            </image>
            <clip>
              <near>0.02</near>
              <far>300</far>
            </clip>
            <noise>
              <type>gaussian</type>
              <mean>0</mean>
              <stddev>0.007</stddev>
            </noise>
          </camera>
          <camera name='right'>
            <pose frame=''>0 -0.07 0 0 -0 0</pose>
            <horizontal_fov>1.39626</horizontal_fov>
            <image>
              <width>640</width>
              <height>480</height>
              <format>R8G8B8</format>
            </image>
            <clip>
              <near>0.02</near>
              <far>300</far>
            </clip>
            <noise>
              <type>gaussian</type>
              <mean>0</mean>
              <stddev>0.007</stddev>
            </noise>
          </camera>
          <plugin name='stereo_camera_controller' filename='libgazebo_ros_multicamera.so'>
            <alwaysOn>true</alwaysOn>
            <updateRate>0.0</updateRate>
            <cameraName>zed/camera</cameraName>
            <imageTopicName>image_raw</imageTopicName>
            <cameraInfoTopicName>camera_info</cameraInfoTopicName>
            <frameName>left_camera_optical_frame</frameName>
            <hackBaseline>0.07</hackBaseline>
            <distortionK1>0.0</distortionK1>
            <distortionK2>0.0</distortionK2>
            <distortionK3>0.0</distortionK3>
            <distortionT1>0.0</distortionT1>
            <distortionT2>0.0</distortionT2>
            <robotNamespace>/</robotNamespace>
          </plugin>
          <pose frame=''>0.394294 0.06775 0.02777 0 -0 0</pose>
        </sensor>
        <self_collide>0</self_collide>
        <kinematic>0</kinematic>
      </link>
      <joint name='arm_joint' type='revolute'>
        <child>arm_upper</child>
        <parent>sled_hoz</parent>
        <axis>
          <xyz>0 1 0</xyz>
          <limit>
            <lower>-0.8</lower>
            <upper>0.31</upper>
            <effort>1e+06</effort>
            <velocity>0.1</velocity>
          </limit>
          <dynamics>
            <damping>0.1</damping>
            <friction>0</friction>
            <spring_reference>0</spring_reference>
            <spring_stiffness>0</spring_stiffness>
          </dynamics>
          <use_parent_model_frame>1</use_parent_model_frame>
        </axis>
      </joint>
      <link name='bucket'>
        <pose frame=''>0.619717 0 0.353717 0 0.785398 0</pose>
        <inertial>
          <pose frame=''>0 0 0 0 -0 0</pose>
          <mass>2.45</mass>
          <inertia>
            <ixx>0.19</ixx>
            <ixy>0</ixy>
            <ixz>0</ixz>
            <iyy>0.03</iyy>
            <iyz>0</iyz>
            <izz>0.17</izz>
          </inertia>
        </inertial>
        <collision name='bucket_collision'>
          <pose frame=''>0.08 0 0.015 0 -0 0</pose>
          <geometry>
            <mesh>
              <scale>1 1 1</scale>
              <uri>/home/jericho/catkin_ws/src/usr_simulation/amee_description/meshes/visual/bucket.dae</uri>
            </mesh>
          </geometry>
          <surface>
            <contact>
              <ode/>
            </contact>
            <friction>
              <ode>
                <mu>0.2</mu>
                <mu2>0.2</mu2>
              </ode>
              <torsional>
                <ode/>
              </torsional>
            </friction>
            <bounce/>
          </surface>
          <max_contacts>10</max_contacts>
        </collision>
        <visual name='bucket_visual'>
          <pose frame=''>0.08 0 0.015 0 -0 0</pose>
          <geometry>
            <mesh>
              <scale>1 1 1</scale>
              <uri>/home/jericho/catkin_ws/src/usr_simulation/amee_description/meshes/visual/bucket_visual.dae</uri>
            </mesh>
          </geometry>
          <material>
            <script>
              <name>Gazebo/Grey</name>
              <uri>file://media/materials/scripts/gazebo.material</uri>
            </script>
          </material>
        </visual>
        <gravity>1</gravity>
        <velocity_decay/>
        <self_collide>0</self_collide>
        <kinematic>0</kinematic>
      </link>
      <joint name='bucket_joint' type='revolute'>
        <child>bucket</child>
        <parent>arm_upper</parent>
        <axis>
          <xyz>0 1 0</xyz>
          <limit>
            <lower>-1.693</lower>
            <upper>0.384</upper>
            <effort>100000</effort>
            <velocity>1</velocity>
          </limit>
          <dynamics>
            <damping>0.1</damping>
            <friction>0</friction>
            <spring_reference>0</spring_reference>
            <spring_stiffness>0</spring_stiffness>
          </dynamics>
          <use_parent_model_frame>1</use_parent_model_frame>
        </axis>
      </joint>
      <plugin name='gazebo_ros_control' filename='libgazebo_ros_control.so'>
        <robotNamespace>/</robotNamespace>
        <robotSimType>gazebo_ros_control/DefaultRobotHWSim</robotSimType>
      </plugin>
      <static>0</static>
      <plugin name='imu_plugin' filename='libgazebo_ros_imu.so'>
        <alwaysOn>true</alwaysOn>
        <topicName>imu/data</topicName>
        <serviceName>imu_service</serviceName>
        <gaussianNoise>0.0</gaussianNoise>
        <updateRate>20.0</updateRate>
        <robotNamespace>/</robotNamespace>
        <bodyName>base_link</bodyName>
        <xyzOffset>0 0 -0.165375</xyzOffset>
        <rpyOffset>0 -0 0</rpyOffset>
      </plugin>
      <pose frame=''>-2.1 2.8 2 0 -0 0</pose>
    </model>
    <light name='user_point_light_0' type='point'>
      <pose frame=''>1.06032 7.15449 1 0 -0 0</pose>
      <diffuse>0.5 0.5 0.5 1</diffuse>
      <specular>0.1 0.1 0.1 1</specular>
      <attenuation>
        <range>20</range>
        <constant>0.5</constant>
        <linear>0.01</linear>
        <quadratic>0.001</quadratic>
      </attenuation>
      <cast_shadows>0</cast_shadows>
      <direction>0 0 -1</direction>
    </light>
    <state world_name='default'>
      <sim_time>96 843000000</sim_time>
      <real_time>192 537430957</real_time>
      <wall_time>1506796070 464008513</wall_time>
      <iterations>96843</iterations>
      <model name='amee'>
        <pose frame=''>-0.329451 2.70315 -0.020375 -1e-06 1e-06 -1.55808</pose>
        <scale>1 1 1</scale>
        <link name='arm_upper'>
          <pose frame=''>-0.33075 2.80539 0.6785 -1e-06 -0.503743 -1.55808</pose>
          <velocity>0.001028 0.001917 0.001836 0.002954 0.001418 -0.000115</velocity>
          <acceleration>-0.954138 5.37995 3.13233 0.040914 1.49749 -1.84837</acceleration>
          <wrench>-2.39489 13.5037 7.86216 0 -0 0</wrench>
        </link>
        <link name='base_link'>
          <pose frame=''>-0.329451 2.70315 -0.020375 -1e-06 1e-06 -1.55808</pose>
          <velocity>4.7e-05 -0.000213 0.002879 -0.010544 0.001202 -8.4e-05</velocity>
          <acceleration>0.533677 3.66058 6.05614 2.08667 1.03355 -2.41676</acceleration>
          <wrench>1.62825 11.1684 18.4773 0 -0 0</wrench>
        </link>
        <link name='bucket'>
          <pose frame=''>-0.320593 2.00656 0.724715 -5e-06 -1.21835 -1.55808</pose>
          <velocity>0.001033 0.001779 -0.000535 -0.002033 0.001329 -0.000152</velocity>
          <acceleration>1.17233 5.17389 -1.11104 -1.69481 -0.369745 2.97729</acceleration>
          <wrench>2.87221 12.676 -2.72205 0 -0 0</wrench>
        </link>
        <link name='left_front_wheel_link'>
          <pose frame=''>-0.021266 2.45455 0.145 -4e-06 -0.628935 -1.55808</pose>
          <velocity>0.000272 0.001525 0.005233 -0.010511 0.001876 -0.00011</velocity>
          <acceleration>0.841066 3.95853 14.2375 -0.535371 -1.23585 -2.17375</acceleration>
          <wrench>7.23317 34.0433 122.443 0 -0 0</wrench>
        </link>
        <link name='left_rear_wheel_link'>
          <pose frame=''>-0.027687 2.95951 0.145 -4e-06 -0.684607 -1.55808</pose>
          <velocity>0.000195 0.00164 7e-05 -0.011111 0.001334 0.000439</velocity>
          <acceleration>-0.067547 4.23988 -0.165002 2.36549 -0.569247 0.716458</acceleration>
          <wrench>-0.580903 36.463 -1.41902 0 -0 0</wrench>
        </link>
        <link name='right_front_wheel_link'>
          <pose frame=''>-0.631216 2.4468 0.145 3.14159 0.149858 -1.55808</pose>
          <velocity>0.000289 0.001525 0.005782 -0.010503 0.001995 0.000207</velocity>
          <acceleration>0.99709 3.42784 12.103 2.50943 -1.46563 1.42442</acceleration>
          <wrench>8.57497 29.4795 104.086 0 -0 0</wrench>
        </link>
        <link name='right_rear_wheel_link'>
          <pose frame=''>-0.637637 2.95175 0.145 -3.14159 0.104143 -1.55808</pose>
          <velocity>9.1e-05 0.001598 9.7e-05 -0.011168 0.000608 -0.000351</velocity>
          <acceleration>-0.248395 3.68795 -2.92054 2.52544 -1.34857 2.56801</acceleration>
          <wrench>-2.1362 31.7164 -25.1166 0 -0 0</wrench>
        </link>
        <link name='sled_hoz'>
          <pose frame=''>-0.329451 2.70315 0.23325 -2e-06 1e-06 -1.55808</pose>
          <velocity>0.000446 -0.002766 0.002906 -0.010521 0.001268 -0.000125</velocity>
          <acceleration>-0.170895 -2.0708 3.72922 -1.91994 0.16924 1.61987</acceleration>
          <wrench>-2.60615 -31.5797 56.8707 0 -0 0</wrench>
        </link>
      </model>
      <model name='ground_plane'>
        <pose frame=''>0 0 0 0 -0 0</pose>
        <scale>1 1 1</scale>
        <link name='link'>
          <pose frame=''>0 0 0 0 -0 0</pose>
          <velocity>0 0 0 0 -0 0</velocity>
          <acceleration>0 0 0 0 -0 0</acceleration>
          <wrench>0 0 0 0 -0 0</wrench>
        </link>
      </model>
      <model name='nasa_arena'>
        <pose frame=''>0 0 0 0 -0 0</pose>
        <scale>1 1 1</scale>
        <link name='body'>
          <pose frame=''>0 0 0 0 -0 0</pose>
          <velocity>0 0 0 0 -0 0</velocity>
          <acceleration>0 0 0 0 -0 0</acceleration>
          <wrench>0 0 0 0 -0 0</wrench>
        </link>
      </model>
      <light name='sun'>
        <pose frame=''>0 0 10 0 -0 0</pose>
      </light>
      <light name='user_point_light_0'>
        <pose frame=''>0.0451 4.31614 1 0 -0 0</pose>
      </light>
    </state>
    <gui fullscreen='0'>
      <camera name='user_camera'>
        <pose frame=''>3.26353 13.4262 4.36947 -0 0.423643 -2.10699</pose>
        <view_controller>orbit</view_controller>
        <projection_type>perspective</projection_type>
      </camera>
    </gui>
  </world>
</sdf>
